Workbook

Sheet LÉEME 🐔
A1: 🐔⚽ FIXTURE MUNDIAL 2026 — LA POLLA DE ALAMEDA (versión Excel) ⚽🐔
A3: Pa'l parcero al que le gusta el Excel más que el WhatsApp 😂. Este archivo hace la magia solo:
A5: 📋 HOJA 'FASE DE GRUPOS': escribe los goles en las casillas amarillas y…
A6: 📊 HOJA 'TABLAS': las posiciones de los 12 grupos se calculan SOLAS (puntos, goles, diferencia y posición). ¡No tocas nada!
A7: 🏆 HOJA 'ELIMINATORIAS': el cuadro completo desde 16avos hasta la final, con fechas y estadios (hora Colombia).
A9: ⚽ Recuerda: ganar = 3 pts, empate = 1, perder = 0. Clasifican los 2 primeros de cada grupo + los 8 mejores terceros.
A10: 📈 Si dos quedan iguales: desempata la diferencia de goles, luego los goles a favor.
A12: 🎯 ¿Quieres JUGAR la polla de verdad y ganar billete pa' la natillera? Esto es solo pa' practicar.
A13: La buena está en la app (te calcula puntos, te avisa morosos y trae hasta simulador): pollamundialnatillera.vercel.app
A15: Hecho con cariño por INPLUX SAS · prohibido copiarlo: la gallina tiene abogados 🐔⚖️

Sheet FASE DE GRUPOS
A1: 🐔 Escribe los goles SOLO en las columnas amarillas (GL = goles local · GV = goles visita)
A2: P# | B2: Grupo | C2: LOCAL | D2: GL | E2: GV | F2: VISITANTE | G2: Fecha (Col) | H2: Estadio
A3: 1 | B3: A | C3: México | F3: Sudáfrica | G3: jue 11 jun · 2:00 PM | H3: Mexico City Stadium
A4: 2 | B4: A | C4: Corea del Sur | F4: Chequia | G4: jue 11 jun · 9:00 PM | H4: Guadalajara Stadium
A5: 25 | B5: A | C5: Chequia | F5: Sudáfrica | G5: jue 18 jun · 11:00 AM | H5: Atlanta Stadium
A6: 28 | B6: A | C6: México | F6: Corea del Sur | G6: jue 18 jun · 8:00 PM | H6: Guadalajara Stadium
A7: 53 | B7: A | C7: Chequia | F7: México | G7: mié 24 jun · 8:00 PM | H7: Mexico City Stadium
A8: 54 | B8: A | C8: Sudáfrica | F8: Corea del Sur | G8: mié 24 jun · 8:00 PM | H8: Monterrey Stadium
A10: 3 | B10: B | C10: Canadá | F10: Bosnia | G10: vie 12 jun · 2:00 PM | H10: Toronto Stadium
A11: 8 | B11: B | C11: Catar | F11: Suiza | G11: sáb 13 jun · 2:00 PM | H11: San Francisco Bay Area Stadium
A12: 26 | B12: B | C12: Suiza | F12: Bosnia | G12: jue 18 jun · 2:00 PM | H12: Los Angeles Stadium
A13: 27 | B13: B | C13: Canadá | F13: Catar | G13: jue 18 jun · 5:00 PM | H13: BC Place Vancouver
A14: 51 | B14: B | C14: Suiza | F14: Canadá | G14: mié 24 jun · 2:00 PM | H14: BC Place Vancouver
A15: 52 | B15: B | C15: Bosnia | F15: Catar | G15: mié 24 jun · 2:00 PM | H15: Seattle Stadium
... A85: 68 | B85: L | C85: Croacia | F85: Ghana | G85: sáb 27 jun · 4:00 PM | H85: Philadelphia Stadium

Sheet TABLAS
A1: 📊 TABLAS DE POSICIONES — se llenan solas con los goles de la hoja anterior. Verde = clasifica 1º/2º.
A2: GRUPO A
A3: POS | B3: EQUIPO | C3: PJ | D3: G | E3: E | F3: P | G3: GF | H3: GC | I3: DIF | J3: PTS
A4: =1+SUMPRODUCT(($J$4:$J$7>$J$4)*1)+SUMPRODUCT(($J$4:$J$7=$J$4)*($I$4:$I$7>$I$4)*1)+SUMPRODUCT(($J$4:$J$7=$J$4)*($I$4:$I$7=$I$4)*($G$4:$G$7>$G$4)*1) | B4: México | C4: =SUMPRODUCT(('FASE DE GRUPOS'!$C$3:$C$8=$B$4)*('FASE DE GRUPOS'!$D$3:$D$8<>""))+SUMPRODUCT(('FASE DE GRUPOS'!$F$3:$F$8=$B$4)*('FASE DE GRUPOS'!$E$3:$E$8<>"")) | D4: =SUMPRODUCT(('FASE DE GRUPOS'!$C$3:$C$8=$B$4)*('FASE DE GRUPOS'!$D$3:$D$8>'FASE DE GRUPOS'!$E$3:$E$8)*('FASE DE GRUPOS'!$D$3:$D$8<>""))+SUMPRODUCT(('FASE DE GRUPOS'!$F$3:$F$8=$B$4)*('FASE DE GRUPOS'!$E$3:$E$8>'FASE DE GRUPOS'!$D$3:$D$8)*('FASE DE GRUPOS'!$E$3:$E$8<>"")) | E4: =SUMPRODUCT(('FASE DE GRUPOS'!$C$3:$C$8=$B$4)*('FASE DE GRUPOS'!$D$3:$D$8='FASE DE GRUPOS'!$E$3:$E$8)*('FASE DE GRUPOS'!$D$3:$D$8<>""))+SUMPRODUCT(('FASE DE GRUPOS'!$F$3:$F$8=$B$4)*('FASE DE GRUPOS'!$E$3:$E$8='FASE DE GRUPOS'!$D$3:$D$8)*('FASE DE GRUPOS'!$E$3:$E$8<>"")) | F4: =$C$4-$D$4-$E$4 | G4: =SUMPRODUCT(('FASE DE GRUPOS'!$C$3:$C$8=$B$4)*'FASE DE GRUPOS'!$D$3:$D$8)+SUMPRODUCT(('FASE DE GRUPOS'!$F$3:$F$8=$B$4)*'FASE DE GRUPOS'!$E$3:$E$8) | H4: =SUMPRODUCT(('FASE DE GRUPOS'!$C$3:$C$8=$B$4)*'FASE DE GRUPOS'!$E$3:$E$8)+SUMPRODUCT(('FASE DE GRUPOS'!$F$3:$F$8=$B$4)*'FASE DE GRUPOS'!$D$3:$D$8) | I4: =$G$4-$H$4 | J4: =3*$D$4+$E$4
A5: =1+SUMPRODUCT(($J$4:$J$7>$J$5)*1)+SUMPRODUCT(($J$4:$J$7=$J$5)*($I$4:$I$7>$I$5)*1)+SUMPRODUCT(($J$4:$J$7=$J$5)*($I$4:$I$7=$I$5)*($G$4:$G$7>$G$5)*1) | B5: Sudáfrica | C5: =SUMPRODUCT(('FASE DE GRUPOS'!$C$3:$C$8=$B$5)*('FASE DE GRUPOS'!$D$3:$D$8<>""))+SUMPRODUCT(('FASE DE GRUPOS'!$F$3:$F$8=$B$5)*('FASE DE GRUPOS'!$E$3:$E$8<>"")) | D5: =SUMPRODUCT(('FASE DE GRUPOS'!$C$3:$C$8=$B$5)*('FASE DE GRUPOS'!$D$3:$D$8>'FASE DE GRUPOS'!$E$3:$E$8)*('FASE DE GRUPOS'!$D$3:$D$8<>""))+SUMPRODUCT(('FASE DE GRUPOS'!$F$3:$F$8=$B$5)*('FASE DE GRUPOS'!$E$3:$E$8>'FASE DE GRUPOS'!$D$3:$D$8)*('FASE DE GRUPOS'!$E$3:$E$8<>"")) | E5: =SUMPRODUCT(('FASE DE GRUPOS'!$C$3:$C$8=$B$5)*('FASE DE GRUPOS'!$D$3:$D$8='FASE DE GRUPOS'!$E$3:$E$8)*('FASE DE GRUPOS'!$D$3:$D$8<>""))+SUMPRODUCT(('FASE DE GRUPOS'!$F$3:$F$8=$B$5)*('FASE DE GRUPOS'!$E$3:$E$8='FASE DE GRUPOS'!$D$3:$D$8)*('FASE DE GRUPOS'!$E$3:$E$8<>"")) | F5: =$C$5-$D$5-$E$5 | G5: =SUMPRODUCT(('FASE DE GRUPOS'!$C$3:$C$8=$B$5)*'FASE DE GRUPOS'!$D$3:$D$8)+SUMPRODUCT(('FASE DE GRUPOS'!$F$3:$F$8=$B$5)*'FASE DE GRUPOS'!$E$3:$E$8) | H5: =SUMPRODUCT(('FASE DE GRUPOS'!$C$3:$C$8=$B$5)*'FASE DE GRUPOS'!$E$3:$E$8)+SUMPRODUCT(('FASE DE GRUPOS'!$F$3:$F$8=$B$5)*'FASE DE GRUPOS'!$D$3:$D$8) | I5: =$G$5-$H$5 | J5: =3*$D$5+$E$5
A6: =1+SUMPRODUCT(($J$4:$J$7>$J$6)*1)+SUMPRODUCT(($J$4:$J$7=$J$6)*($I$4:$I$7>$I$6)*1)+SUMPRODUCT(($J$4:$J$7=$J$6)*($I$4:$I$7=$I$6)*($G$4:$G$7>$G$6)*1) | B6: Corea del Sur | C6: =SUMPRODUCT(('FASE DE GRUPOS'!$C$3:$C$8=$B$6)*('FASE DE GRUPOS'!$D$3:$D$8<>""))+SUMPRODUCT(('FASE DE GRUPOS'!$F$3:$F$8=$B$6)*('FASE DE GRUPOS'!$E$3:$E$8<>"")) | D6: =SUMPRODUCT(('FASE DE GRUPOS'!$C$3:$C$8=$B$6)*('FASE DE GRUPOS'!$D$3:$D$8>'FASE DE GRUPOS'!$E$3:$E$8)*('FASE DE GRUPOS'!$D$3:$D$8<>""))+SUMPRODUCT(('FASE DE GRUPOS'!$F$3:$F$8=$B$6)*('FASE DE GRUPOS'!$E$3:$E$8>'FASE DE GRUPOS'!$D$3:$D$8)*('FASE DE GRUPOS'!$E$3:$E$8<>"")) | E6: =SUMPRODUCT(('FASE DE GRUPOS'!$C$3:$C$8=$B$6)*('FASE DE GRUPOS'!$D$3:$D$8='FASE DE GRUPOS'!$E$3:$E$8)*('FASE DE GRUPOS'!$D$3:$D$8<>""))+SUMPRODUCT(('FASE DE GRUPOS'!$F$3:$F$8=$B$6)*('FASE DE GRUPOS'!$E$3:$E$8='FASE DE GRUPOS'!$D$3:$D$8)*('FASE DE GRUPOS'!$E$3:$E$8<>"")) | F6: =$C$6-$D$6-$E$6 | G6: =SUMPRODUCT(('FASE DE GRUPOS'!$C$3:$C$8=$B$6)*'FASE DE GRUPOS'!$D$3:$D$8)+SUMPRODUCT(('FASE DE GRUPOS'!$F$3:$F$8=$B$6)*'FASE DE GRUPOS'!$E$3:$E$8) | H6: =SUMPRODUCT(('FASE DE GRUPOS'!$C$3:$C$8=$B$6)*'FASE DE GRUPOS'!$E$3:$E$8)+SUMPRODUCT(('FASE DE GRUPOS'!$F$3:$F$8=$B$6)*'FASE DE GRUPOS'!$D$3:$D$8) | I6: =$G$6-$H$6 | J6: =3*$D$6+$E$6
A7: =1+SUMPRODUCT(($J$4:$J$7>$J$7)*1)+SUMPRODUCT(($J$4:$J$7=$J$7)*($I$4:$I$7>$I$7)*1)+SUMPRODUCT(($J$4:$J$7=$J$7)*($I$4:$I$7=$I$7)*($G$4:$G$7>$G$7)*1) | B7: Chequia | C7: =SUMPRODUCT(('FASE DE GRUPOS'!$C$3:$C$8=$B$7)*('FASE DE GRUPOS'!$D$3:$D$8<>""))+SUMPRODUCT(('FASE DE GRUPOS'!$F$3:$F$8=$B$7)*('FASE DE GRUPOS'!$E$3:$E$8<>"")) | D7: =SUMPRODUCT(('FASE DE GRUPOS'!$C$3:$C$8=$B$7)*('FASE DE GRUPOS'!$D$3:$D$8>'FASE DE GRUPOS'!$E$3:$E$8)*('FASE DE GRUPOS'!$D$3:$D$8<>""))+SUMPRODUCT(('FASE DE GRUPOS'!$F$3:$F$8=$B$7)*('FASE DE GRUPOS'!$E$3:$E$8>'FASE DE GRUPOS'!$D$3:$D$8)*('FASE DE GRUPOS'!$E$3:$E$8<>"")) | E7: =SUMPRODUCT(('FASE DE GRUPOS'!$C$3:$C$8=$B$7)*('FASE DE GRUPOS'!$D$3:$D$8='FASE DE GRUPOS'!$E$3:$E$8)*('FASE DE GRUPOS'!$D$3:$D$8<>""))+SUMPRODUCT(('FASE DE GRUPOS'!$F$3:$F$8=$B$7)*('FASE DE GRUPOS'!$E$3:$E$8='FASE DE GRUPOS'!$D$3:$D$8)*('FASE DE GRUPOS'!$E$3:$E$8<>"")) | F7: =$C$7-$D$7-$E$7 | G7: =SUMPRODUCT(('FASE DE GRUPOS'!$C$3:$C$8=$B$7)*'FASE DE GRUPOS'!$D$3:$D$8)+SUMPRODUCT(('FASE DE GRUPOS'!$F$3:$F$8=$B$7)*'FASE DE GRUPOS'!$E$3:$E$8) | H7: =SUMPRODUCT(('FASE DE GRUPOS'!$C$3:$C$8=$B$7)*'FASE DE GRUPOS'!$E$3:$E$8)+SUMPRODUCT(('FASE DE GRUPOS'!$F$3:$F$8=$B$7)*'FASE DE GRUPOS'!$D$3:$D$8) | I7: =$G$7-$H$7 | J7: =3*$D$7+$E$7
A9: GRUPO B
A10: POS | B10: EQUIPO | C10: PJ | D10: G | E10: E | F10: P | G10: GF | H10: GC | I10: DIF | J10: PTS
A11: =1+SUMPRODUCT(($J$11:$J$14>$J$11)*1)+SUMPRODUCT(($J$11:$J$14=$J$11)*($I$11:$I$14>$I$11)*1)+SUMPRODUCT(($J$11:$J$14=$J$11)*($I$11:$I$14=$I$11)*($G$11:$G$14>$G$11)*1) | B11: Canadá | C11: =SUMPRODUCT(('FASE DE GRUPOS'!$C$10:$C$15=$B$11)*('FASE DE GRUPOS'!$D$10:$D$15<>""))+SUMPRODUCT(('FASE DE GRUPOS'!$F$10:$F$15=$B$11)*('FASE DE GRUPOS'!$E$10:$E$15<>"")) | D11: =SUMPRODUCT(('FASE DE GRUPOS'!$C$10:$C$15=$B$11)*('FASE DE GRUPOS'!$D$10:$D$15>'FASE DE GRUPOS'!$E$10:$E$15)*('FASE DE GRUPOS'!$D$10:$D$15<>""))+SUMPRODUCT(('FASE DE GRUPOS'!$F$10:$F$15=$B$11)*('FASE DE GRUPOS'!$E$10:$E$15>'FASE DE GRUPOS'!$D$10:$D$15)*('FASE DE GRUPOS'!$E$10:$E$15<>"")) | E11: =SUMPRODUCT(('FASE DE GRUPOS'!$C$10:$C$15=$B$11)*('FASE DE GRUPOS'!$D$10:$D$15='FASE DE GRUPOS'!$E$10:$E$15)*('FASE DE GRUPOS'!$D$10:$D$15<>""))+SUMPRODUCT(('FASE DE GRUPOS'!$F$10:$F$15=$B$11)*('FASE DE GRUPOS'!$E$10:$E$15='FASE DE GRUPOS'!$D$10:$D$15)*('FASE DE GRUPOS'!$E$10:$E$15<>"")) | F11: =$C$11-$D$11-$E$11 | G11: =SUMPRODUCT(('FASE DE GRUPOS'!$C$10:$C$15=$B$11)*'FASE DE GRUPOS'!$D$10:$D$15)+SUMPRODUCT(('FASE DE GRUPOS'!$F$10:$F$15=$B$11)*'FASE DE GRUPOS'!$E$10:$E$15) | H11: =SUMPRODUCT(('FASE DE GRUPOS'!$C$10:$C$15=$B$11)*'FASE DE GRUPOS'!$E$10:$E$15)+SUMPRODUCT(('FASE DE GRUPOS'!$F$10:$F$15=$B$11)*'FASE DE GRUPOS'!$D$10:$D$15) | I11: =$G$11-$H$11 | J11: =3*$D$11+$E$11
A12: =1+SUMPRODUCT(($J$11:$J$14>$J$12)*1)+SUMPRODUCT(($J$11:$J$14=$J$12)*($I$11:$I$14>$I$12)*1)+SUMPRODUCT(($J$11:$J$14=$J$12)*($I$11:$I$14=$I$12)*($G$11:$G$14>$G$12)*1) | B12: Bosnia | C12: =SUMPRODUCT(('FASE DE GRUPOS'!$C$10:$C$15=$B$12)*('FASE DE GRUPOS'!$D$10:$D$15<>""))+SUMPRODUCT(('FASE DE GRUPOS'!$F$10:$F$15=$B$12)*('FASE DE GRUPOS'!$E$10:$E$15<>"")) | D12: =SUMPRODUCT(('FASE DE GRUPOS'!$C$10:$C$15=$B$12)*('FASE DE GRUPOS'!$D$10:$D$15>'FASE DE GRUPOS'!$E$10:$E$15)*('FASE DE GRUPOS'!$D$10:$D$15<>""))+SUMPRODUCT(('FASE DE GRUPOS'!$F$10:$F$15=$B$12)*('FASE DE GRUPOS'!$E$10:$E$15>'FASE DE GRUPOS'!$D$10:$D$15)*('FASE DE GRUPOS'!$E$10:$E$15<>"")) | E12: =SUMPRODUCT(('FASE DE GRUPOS'!$C$10:$C$15=$B$12)*('FASE DE GRUPOS'!$D$10:$D$15='FASE DE GRUPOS'!$E$10:$E$15)*('FASE DE GRUPOS'!$D$10:$D$15<>""))+SUMPRODUCT(('FASE DE GRUPOS'!$F$10:$F$15=$B$12)*('FASE DE GRUPOS'!$E$10:$E$15='FASE DE GRUPOS'!$D$10:$D$15)*('FASE DE GRUPOS'!$E$10:$E$15<>"")) | F12: =$C$12-$D$12-$E$12 | G12: =SUMPRODUCT(('FASE DE GRUPOS'!$C$10:$C$15=$B$12)*'FASE DE GRUPOS'!$D$10:$D$15)+SUMPRODUCT(('FASE DE GRUPOS'!$F$10:$F$15=$B$12)*'FASE DE GRUPOS'!$E$10:$E$15) | H12: =SUMPRODUCT(('FASE DE GRUPOS'!$C$10:$C$15=$B$12)*'FASE DE GRUPOS'!$E$10:$E$15)+SUMPRODUCT(('FASE DE GRUPOS'!$F$10:$F$15=$B$12)*'FASE DE GRUPOS'!$D$10:$D$15) | I12: =$G$12-$H$12 | J12: =3*$D$12+$E$12
A13: =1+SUMPRODUCT(($J$11:$J$14>$J$13)*1)+SUMPRODUCT(($J$11:$J$14=$J$13)*($I$11:$I$14>$I$13)*1)+SUMPRODUCT(($J$11:$J$14=$J$13)*($I$11:$I$14=$I$13)*($G$11:$G$14>$G$13)*1) | B13: Catar | C13: =SUMPRODUCT(('FASE DE GRUPOS'!$C$10:$C$15=$B$13)*('FASE DE GRUPOS'!$D$10:$D$15<>""))+SUMPRODUCT(('FASE DE GRUPOS'!$F$10:$F$15=$B$13)*('FASE DE GRUPOS'!$E$10:$E$15<>"")) | D13: =SUMPRODUCT(('FASE DE GRUPOS'!$C$10:$C$15=$B$13)*('FASE DE GRUPOS'!$D$10:$D$15>'FASE DE GRUPOS'!$E$10:$E$15)*('FASE DE GRUPOS'!$D$10:$D$15<>""))+SUMPRODUCT(('FASE DE GRUPOS'!$F$10:$F$15=$B$13)*('FASE DE GRUPOS'!$E$10:$E$15>'FASE DE GRUPOS'!$D$10:$D$15)*('FASE DE GRUPOS'!$E$10:$E$15<>"")) | E13: =SUMPRODUCT(('FASE DE GRUPOS'!$C$10:$C$15=$B$13)*('FASE DE GRUPOS'!$D$10:$D$15='FASE DE GRUPOS'!$E$10:$E$15)*('FASE DE GRUPOS'!$D$10:$D$15<>""))+SUMPRODUCT(('FASE DE GRUPOS'!$F$10:$F$15=$B$13)*('FASE DE GRUPOS'!$E$10:$E$15='FASE DE GRUPOS'!$D$10:$D$15)*('FASE DE GRUPOS'!$E$10:$E$15<>"")) | F13: =$C$13-$D$13-$E$13 | G13: =SUMPRODUCT(('FASE DE GRUPOS'!$C$10:$C$15=$B$13)*'FASE DE GRUPOS'!$D$10:$D$15)+SUMPRODUCT(('FASE DE GRUPOS'!$F$10:$F$15=$B$13)*'FASE DE GRUPOS'!$E$10:$E$15) | H13: =SUMPRODUCT(('FASE DE GRUPOS'!$C$10:$C$15=$B$13)*'FASE DE GRUPOS'!$E$10:$E$15)+SUMPRODUCT(('FASE DE GRUPOS'!$F$10:$F$15=$B$13)*'FASE DE GRUPOS'!$D$10:$D$15) | I13: =$G$13-$H$13 | J13: =3*$D$13+$E$13
A14: =1+SUMPRODUCT(($J$11:$J$14>$J$14)*1)+SUMPRODUCT(($J$11:$J$14=$J$14)*($I$11:$I$14>$I$14)*1)+SUMPRODUCT(($J$11:$J$14=$J$14)*($I$11:$I$14=$I$14)*($G$11:$G$14>$G$14)*1) | B14: Suiza | C14: =SUMPRODUCT(('FASE DE GRUPOS'!$C$10:$C$15=$B$14)*('FASE DE GRUPOS'!$D$10:$D$15<>""))+SUMPRODUCT(('FASE DE GRUPOS'!$F$10:$F$15=$B$14)*('FASE DE GRUPOS'!$E$10:$E$15<>"")) | D14: =SUMPRODUCT(('FASE DE GRUPOS'!$C$10:$C$15=$B$14)*('FASE DE GRUPOS'!$D$10:$D$15>'FASE DE GRUPOS'!$E$10:$E$15)*('FASE DE GRUPOS'!$D$10:$D$15<>""))+SUMPRODUCT(('FASE DE GRUPOS'!$F$10:$F$15=$B$14)*('FASE DE GRUPOS'!$E$10:$E$15>'FASE DE GRUPOS'!$D$10:$D$15)*('FASE DE GRUPOS'!$E$10:$E$15<>"")) | E14: =SUMPRODUCT(('FASE DE GRUPOS'!$C$10:$C$15=$B$14)*('FASE DE GRUPOS'!$D$10:$D$15='FASE DE GRUPOS'!$E$10:$E$15)*('FASE DE GRUPOS'!$D$10:$D$15<>""))+SUMPRODUCT(('FASE DE GRUPOS'!$F$10:$F$15=$B$14)*('FASE DE GRUPOS'!$E$10:$E$15='FASE DE GRUPOS'!$D$10:$D$15)*('FASE DE GRUPOS'!$E$10:$E$15<>"")) | F14: =$C$14-$D$14-$E$14 | G14: =SUMPRODUCT(('FASE DE GRUPOS'!$C$10:$C$15=$B$14)*'FASE DE GRUPOS'!$D$10:$D$15)+SUMPRODUCT(('FASE DE GRUPOS'!$F$10:$F$15=$B$14)*'FASE DE GRUPOS'!$E$10:$E$15) | H14: =SUMPRODUCT(('FASE DE GRUPOS'!$C$10:$C$15=$B$14)*'FASE DE GRUPOS'!$E$10:$E$15)+SUMPRODUCT(('FASE DE GRUPOS'!$F$10:$F$15=$B$14)*'FASE DE GRUPOS'!$D$10:$D$15) | I14: =$G$14-$H$14 | J14: =3*$D$14+$E$14
A16: GRUPO C
A17: POS | B17: EQUIPO | C17: PJ | D17: G | E17: E | F17: P | G17: GF | H17: GC | I17: DIF | J17: PTS
A18: =1+SUMPRODUCT(($J$18:$J$21>$J$18)*1)+SUMPRODUCT(($J$18:$J$21=$J$18)*($I$18:$I$21>$I$18)*1)+SUMPRODUCT(($J$18:$J$21=$J$18)*($I$18:$I$21=$I$18)*($G$18:$G$21>$G$18)*1) | B18: Brasil | C18: =SUMPRODUCT(('FASE DE GRUPOS'!$C$17:$C$22=$B$18)*('FASE DE GRUPOS'!$D$17:$D$22<>""))+SUMPRODUCT(('FASE DE GRUPOS'!$F$17:$F$22=$B$18)*('FASE DE GRUPOS'!$E$17:$E$22<>"")) | D18: =SUMPRODUCT(('FASE DE GRUPOS'!$C$17:$C$22=$B$18)*('FASE DE GRUPOS'!$D$17:$D$22>'FASE DE GRUPOS'!$E$17:$E$22)*('FASE DE GRUPOS'!$D$17:$D$22<>""))+SUMPRODUCT(('FASE DE GRUPOS'!$F$17:$F$22=$B$18)*('FASE DE GRUPOS'!$E$17:$E$22>'FASE DE GRUPOS'!$D$17:$D$22)*('FASE DE GRUPOS'!$E$17:$E$22<>"")) | E18: =SUMPRODUCT(('FASE DE GRUPOS'!$C$17:$C$22=$B$18)*('FASE DE GRUPOS'!$D$17:$D$22='FASE DE GRUPOS'!$E$17:$E$22)*('FASE DE GRUPOS'!$D$17:$D$22<>""))+SUMPRODUCT(('FASE DE GRUPOS'!$F$17:$F$22=$B$18)*('FASE DE GRUPOS'!$E$17:$E$22='FASE DE GRUPOS'!$D$17:$D$22)*('FASE DE GRUPOS'!$E$17:$E$22<>"")) | F18: =$C$18-$D$18-$E$18 | G18: =SUMPRODUCT(('FASE DE GRUPOS'!$C$17:$C$22=$B$18)*'FASE DE GRUPOS'!$D$17:$D$22)+SUMPRODUCT(('FASE DE GRUPOS'!$F$17:$F$22=$B$18)*'FASE DE GRUPOS'!$E$17:$E$22) | H18: =SUMPRODUCT(('FASE DE GRUPOS'!$C$17:$C$22=$B$18)*'FASE DE GRUPOS'!$E$17:$E$22)+SUMPRODUCT(('FASE DE GRUPOS'!$F$17:$F$22=$B$18)*'FASE DE GRUPOS'!$D$17:$D$22) | I18: =$G$18-$H$18 | J18: =3*$D$18+$E$18
A19: =1+SUMPRODUCT(($J$18:$J$21>$J$19)*1)+SUMPRODUCT(($J$18:$J$21=$J$19)*($I$18:$I$21>$I$19)*1)+SUMPRODUCT(($J$18:$J$21=$J$19)*($I$18:$I$21=$I$19)*($G$18:$G$21>$G$19)*1) | B19: Marruecos | C19: =SUMPRODUCT(('FASE DE GRUPOS'!$C$17:$C$22=$B$19)*('FASE DE GRUPOS'!$D$17:$D$22<>""))+SUMPRODUCT(('FASE DE GRUPOS'!$F$17:$F$22=$B$19)*('FASE DE GRUPOS'!$E$17:$E$22<>"")) | D19: =SUMPRODUCT(('FASE DE GRUPOS'!$C$17:$C$22=$B$19)*('FASE DE GRUPOS'!$D$17:$D$22>'FASE DE GRUPOS'!$E$17:$E$22)*('FASE DE GRUPOS'!$D$17:$D$22<>""))+SUMPRODUCT(('FASE DE GRUPOS'!$F$17:$F$22=$B$19)*('FASE DE GRUPOS'!$E$17:$E$22>'FASE DE GRUPOS'!$D$17:$D$22)*('FASE DE GRUPOS'!$E$17:$E$22<>"")) | E19: =SUMPRODUCT(('FASE DE GRUPOS'!$C$17:$C$22=$B$19)*('FASE DE GRUPOS'!$D$17:$D$22='FASE DE GRUPOS'!$E$17:$E$22)*('FASE DE GRUPOS'!$D$17:$D$22<>""))+SUMPRODUCT(('FASE DE GRUPOS'!$F$17:$F$22=$B$19)*('FASE DE GRUPOS'!$E$17:$E$22='FASE DE GRUPOS'!$D$17:$D$22)*('FASE DE GRUPOS'!$E$17:$E$22<>"")) | F19: =$C$19-$D$19-$E$19 | G19: =SUMPRODUCT(('FASE DE GRUPOS'!$C$17:$C$22=$B$19)*'FASE DE GRUPOS'!$D$17:$D$22)+SUMPRODUCT(('FASE DE GRUPOS'!$F$17:$F$22=$B$19)*'FASE DE GRUPOS'!$E$17:$E$22) | H19: =SUMPRODUCT(('FASE DE GRUPOS'!$C$17:$C$22=$B$19)*'FASE DE GRUPOS'!$E$17:$E$22)+SUMPRODUCT(('FASE DE GRUPOS'!$F$17:$F$22=$B$19)*'FASE DE GRUPOS'!$D$17:$D$22) | I19: =$G$19-$H$19 | J19: =3*$D$19+$E$19
A20: =1+SUMPRODUCT(($J$18:$J$21>$J$20)*1)+SUMPRODUCT(($J$18:$J$21=$J$20)*($I$18:$I$21>$I$20)*1)+SUMPRODUCT(($J$18:$J$21=$J$20)*($I$18:$I$21=$I$20)*($G$18:$G$21>$G$20)*1) | B20: Haití | C20: =SUMPRODUCT(('FASE DE GRUPOS'!$C$17:$C$22=$B$20)*('FASE DE GRUPOS'!$D$17:$D$22<>""))+SUMPRODUCT(('FASE DE GRUPOS'!$F$17:$F$22=$B$20)*('FASE DE GRUPOS'!$E$17:$E$22<>"")) | D20: =SUMPRODUCT(('FASE DE GRUPOS'!$C$17:$C$22=$B$20)*('FASE DE GRUPOS'!$D$17:$D$22>'FASE DE GRUPOS'!$E$17:$E$22)*('FASE DE GRUPOS'!$D$17:$D$22<>""))+SUMPRODUCT(('FASE DE GRUPOS'!$F$17:$F$22=$B$20)*('FASE DE GRUPOS'!$E$17:$E$22>'FASE DE GRUPOS'!$D$17:$D$22)*('FASE DE GRUPOS'!$E$17:$E$22<>"")) | E20: =SUMPRODUCT(('FASE DE GRUPOS'!$C$17:$C$22=$B$20)*('FASE DE GRUPOS'!$D$17:$D$22='FASE DE GRUPOS'!$E$17:$E$22)*('FASE DE GRUPOS'!$D$17:$D$22<>""))+SUMPRODUCT(('FASE DE GRUPOS'!$F$17:$F$22=$B$20)*('FASE DE GRUPOS'!$E$17:$E$22='FASE DE GRUPOS'!$D$17:$D$22)*('FASE DE GRUPOS'!$E$17:$E$22<>"")) | F20: =$C$20-$D$20-$E$20 | G20: =SUMPRODUCT(('FASE DE GRUPOS'!$C$17:$C$22=$B$20)*'FASE DE GRUPOS'!$D$17:$D$22)+SUMPRODUCT(('FASE DE GRUPOS'!$F$17:$F$22=$B$20)*'FASE DE GRUPOS'!$E$17:$E$22) | H20: =SUMPRODUCT(('FASE DE GRUPOS'!$C$17:$C$22=$B$20)*'FASE DE GRUPOS'!$E$17:$E$22)+SUMPRODUCT(('FASE DE GRUPOS'!$F$17:$F$22=$B$20)*'FASE DE GRUPOS'!$D$17:$D$22) | I20: =$G$20-$H$20 | J20: =3*$D$20+$E$20
A21: =1+SUMPRODUCT(($J$18:$J$21>$J$21)*1)+SUMPRODUCT(($J$18:$J$21=$J$21)*($I$18:$I$21>$I$21)*1)+SUMPRODUCT(($J$18:$J$21=$J$21)*($I$18:$I$21=$I$21)*($G$18:$G$21>$G$21)*1) | B21: Escocia | C21: =SUMPRODUCT(('FASE DE GRUPOS'!$C$17:$C$22=$B$21)*('FASE DE GRUPOS'!$D$17:$D$22<>""))+SUMPRODUCT(('FASE DE GRUPOS'!$F$17:$F$22=$B$21)*('FASE DE GRUPOS'!$E$17:$E$22<>"")) | D21: =SUMPRODUCT(('FASE DE GRUPOS'!$C$17:$C$22=$B$21)*('FASE DE GRUPOS'!$D$17:$D$22>'FASE DE GRUPOS'!$E$17:$E$22)*('FASE DE GRUPOS'!$D$17:$D$22<>""))+SUMPRODUCT(('FASE DE GRUPOS'!$F$17:$F$22=$B$21)*('FASE DE GRUPOS'!$E$17:$E$22>'FASE DE GRUPOS'!$D$17:$D$22)*('FASE DE GRUPOS'!$E$17:$E$22<>"")) | E21: =SUMPRODUCT(('FASE DE GRUPOS'!$C$17:$C$22=$B$21)*('FASE DE GRUPOS'!$D$17:$D$22='FASE DE GRUPOS'!$E$17:$E$22)*('FASE DE GRUPOS'!$D$17:$D$22<>""))+SUMPRODUCT(('FASE DE GRUPOS'!$F$17:$F$22=$B$21)*('FASE DE GRUPOS'!$E$17:$E$22='FASE DE GRUPOS'!$D$17:$D$22)*('FASE DE GRUPOS'!$E$17:$E$22<>"")) | F21: =$C$21-$D$21-$E$21 | G21: =SUMPRODUCT(('FASE DE GRUPOS'!$C$17:$C$22=$B$21)*'FASE DE GRUPOS'!$D$17:$D$22)+SUMPRODUCT(('FASE DE GRUPOS'!$F$17:$F$22=$B$21)*'FASE DE GRUPOS'!$E$17:$E$22) | H21: =SUMPRODUCT(('FASE DE GRUPOS'!$C$17:$C$22=$B$21)*'FASE DE GRUPOS'!$E$17:$E$22)+SUMPRODUCT(('FASE DE GRUPOS'!$F$17:$F$22=$B$21)*'FASE DE GRUPOS'!$D$17:$D$22) | I21: =$G$21-$H$21 | J21: =3*$D$21+$E$21
A23: GRUPO D
A24: POS | B24: EQUIPO | C24: PJ | D24: G | E24: E | F24: P | G24: GF | H24: GC | I24: DIF | J24: PTS
A25: =1+SUMPRODUCT(($J$25:$J$28>$J$25)*1)+SUMPRODUCT(($J$25:$J$28=$J$25)*($I$25:$I$28>$I$25)*1)+SUMPRODUCT(($J$25:$J$28=$J$25)*($I$25:$I$28=$I$25)*($G$25:$G$28>$G$25)*1) | B25: Estados Unidos | C25: =SUMPRODUCT(('FASE DE GRUPOS'!$C$24:$C$29=$B$25)*('FASE DE GRUPOS'!$D$24:$D$29<>""))+SUMPRODUCT(('FASE DE GRUPOS'!$F$24:$F$29=$B$25)*('FASE DE GRUPOS'!$E$24:$E$29<>"")) | D25: =SUMPRODUCT(('FASE DE GRUPOS'!$C$24:$C$29=$B$25)*('FASE DE GRUPOS'!$D$24:$D$29>'FASE DE GRUPOS'!$E$24:$E$29)*('FASE DE GRUPOS'!$D$24:$D$29<>""))+SUMPRODUCT(('FASE DE GRUPOS'!$F$24:$F$29=$B$25)*('FASE DE GRUPOS'!$E$24:$E$29>'FASE DE GRUPOS'!$D$24:$D$29)*('FASE DE GRUPOS'!$E$24:$E$29<>"")) | E25: =SUMPRODUCT(('FASE DE GRUPOS'!$C$24:$C$29=$B$25)*('FASE DE GRUPOS'!$D$24:$D$29='FASE DE GRUPOS'!$E$24:$E$29)*('FASE DE GRUPOS'!$D$24:$D$29<>""))+SUMPRODUCT(('FASE DE GRUPOS'!$F$24:$F$29=$B$25)*('FASE DE GRUPOS'!$E$24:$E$29='FASE DE GRUPOS'!$D$24:$D$29)*('FASE DE GRUPOS'!$E$24:$E$29<>"")) | F25: =$C$25-$D$25-$E$25 | G25: =SUMPRODUCT(('FASE DE GRUPOS'!$C$24:$C$29=$B$25)*'FASE DE GRUPOS'!$D$24:$D$29)+SUMPRODUCT(('FASE DE GRUPOS'!$F$24:$F$29=$B$25)*'FASE DE GRUPOS'!$E$24:$E$29) | H25: =SUMPRODUCT(('FASE DE GRUPOS'!$C$24:$C$29=$B$25)*'FASE DE GRUPOS'!$E$24:$E$29)+SUMPRODUCT(('FASE DE GRUPOS'!$F$24:$F$29=$B$25)*'FASE DE GRUPOS'!$D$24:$D$29) | I25: =$G$25-$H$25 | J25: =3*$D$25+$E$25
A26: =1+SUMPRODUCT(($J$25:$J$28>$J$26)*1)+SUMPRODUCT(($J$25:$J$28=$J$26)*($I$25:$I$28>$I$26)*1)+SUMPRODUCT(($J$25:$J$28=$J$26)*($I$25:$I$28=$I$26)*($G$25:$G$28>$G$26)*1) | B26: Paraguay | C26: =SUMPRODUCT(('FASE DE GRUPOS'!$C$24:$C$29=$B$26)*('FASE DE GRUPOS'!$D$24:$D$29<>""))+SUMPRODUCT(('FASE DE GRUPOS'!$F$24:$F$29=$B$26)*('FASE DE GRUPOS'!$E$24:$E$29<>"")) | D26: =SUMPRODUCT(('FASE DE GRUPOS'!$C$24:$C$29=$B$26)*('FASE DE GRUPOS'!$D$24:$D$29>'FASE DE GRUPOS'!$E$24:$E$29)*('FASE DE GRUPOS'!$D$24:$D$29<>""))+SUMPRODUCT(('FASE DE GRUPOS'!$F$24:$F$29=$B$26)*('FASE DE GRUPOS'!$E$24:$E$29>'FASE DE GRUPOS'!$D$24:$D$29)*('FASE DE GRUPOS'!$E$24:$E$29<>"")) | E26: =SUMPRODUCT(('FASE DE GRUPOS'!$C$24:$C$29=$B$26)*('FASE DE GRUPOS'!$D$24:$D$29='FASE DE GRUPOS'!$E$24:$E$29)*('FASE DE GRUPOS'!$D$24:$D$29<>""))+SUMPRODUCT(('FASE DE GRUPOS'!$F$24:$F$29=$B$26)*('FASE DE GRUPOS'!$E$24:$E$29='FASE DE GRUPOS'!$D$24:$D$29)*('FASE DE GRUPOS'!$E$24:$E$29<>"")) | F26: =$C$26-$D$26-$E$26 | G26: =SUMPRODUCT(('FASE DE GRUPOS'!$C$24:$C$29=$B$26)*'FASE DE GRUPOS'!$D$24:$D$29)+SUMPRODUCT(('FASE DE GRUPOS'!$F$24:$F$29=$B$26)*'FASE DE GRUPOS'!$E$24:$E$29) | H26: =SUMPRODUCT(('FASE DE GRUPOS'!$C$24:$C$29=$B$26)*'FASE DE GRUPOS'!$E$24:$E$29)+SUMPRODUCT(('FASE DE GRUPOS'!$F$24:$F$29=$B$26)*'FASE DE GRUPOS'!$D$24:$D$29) | I26: =$G$26-$H$26 | J26: =3*$D$26+$E$26
A27: =1+SUMPRODUCT(($J$25:$J$28>$J$27)*1)+SUMPRODUCT(($J$25:$J$28=$J$27)*($I$25:$I$28>$I$27)*1)+SUMPRODUCT(($J$25:$J$28=$J$27)*($I$25:$I$28=$I$27)*($G$25:$G$28>$G$27)*1) | B27: Australia | C27: =SUMPRODUCT(('FASE DE GRUPOS'!$C$24:$C$29=$B$27)*('FASE DE GRUPOS'!$D$24:$D$29<>""))+SUMPRODUCT(('FASE DE GRUPOS'!$F$24:$F$29=$B$27)*('FASE DE GRUPOS'!$E$24:$E$29<>"")) | D27: =SUMPRODUCT(('FASE DE GRUPOS'!$C$24:$C$29=$B$27)*('FASE DE GRUPOS'!$D$24:$D$29>'FASE DE GRUPOS'!$E$24:$E$29)*('FASE DE GRUPOS'!$D$24:$D$29<>""))+SUMPRODUCT(('FASE DE GRUPOS'!$F$24:$F$29=$B$27)*('FASE DE GRUPOS'!$E$24:$E$29>'FASE DE GRUPOS'!$D$24:$D$29)*('FASE DE GRUPOS'!$E$24:$E$29<>"")) | E27: =SUMPRODUCT(('FASE DE GRUPOS'!$C$24:$C$29=$B$27)*('FASE DE GRUPOS'!$D$24:$D$29='FASE DE GRUPOS'!$E$24:$E$29)*('FASE DE GRUPOS'!$D$24:$D$29<>""))+SUMPRODUCT(('FASE DE GRUPOS'!$F$24:$F$29=$B$27)*('FASE DE GRUPOS'!$E$24:$E$29='FASE DE GRUPOS'!$D$24:$D$29)*('FASE DE GRUPOS'!$E$24:$E$29<>"")) | F27: =$C$27-$D$27-$E$27 | G27: =SUMPRODUCT(('FASE DE GRUPOS'!$C$24:$C$29=$B$27)*'FASE DE GRUPOS'!$D$24:$D$29)+SUMPRODUCT(('FASE DE GRUPOS'!$F$24:$F$29=$B$27)*'FASE DE GRUPOS'!$E$24:$E$29) | H27: =SUMPRODUCT(('FASE DE GRUPOS'!$C$24:$C$29=$B$27)*'FASE DE GRUPOS'!$E$24:$E$29)+SUMPRODUCT(('FASE DE GRUPOS'!$F$24:$F$29=$B$27)*'FASE DE GRUPOS'!$D$24:$D$29) | I27: =$G$27-$H$27 | J27: =3*$D$27+$E$27
A28: =1+SUMPRODUCT(($J$25:$J$28>$J$28)*1)+SUMPRODUCT(($J$25:$J$28=$J$28)*($I$25:$I$28>$I$28)*1)+SUMPRODUCT(($J$25:$J$28=$J$28)*($I$25:$I$28=$I$28)*($G$25:$G$28>$G$28)*1) | B28: Turquía | C28: =SUMPRODUCT(('FASE DE GRUPOS'!$C$24:$C$29=$B$28)*('FASE DE GRUPOS'!$D$24:$D$29<>""))+SUMPRODUCT(('FASE DE GRUPOS'!$F$24:$F$29=$B$28)*('FASE DE GRUPOS'!$E$24:$E$29<>"")) | D28: =SUMPRODUCT(('FASE DE GRUPOS'!$C$24:$C$29=$B$28)*('FASE DE GRUPOS'!$D$24:$D$29>'FASE DE GRUPOS'!$E$24:$E$29)*('FASE DE GRUPOS'!$D$24:$D$29<>""))+SUMPRODUCT(('FASE DE GRUPOS'!$F$24:$F$29=$B$28)*('FASE DE GRUPOS'!$E$24:$E$29>'FASE DE GRUPOS'!$D$24:$D$29)*('FASE DE GRUPOS'!$E$24:$E$29<>"")) | E28: =SUMPRODUCT(('FASE DE GRUPOS'!$C$24:$C$29=$B$28)*('FASE DE GRUPOS'!$D$24:$D$29='FASE DE GRUPOS'!$E$24:$E$29)*('FASE DE GRUPOS'!$D$24:$D$29<>""))+SUMPRODUCT(('FASE DE GRUPOS'!$F$24:$F$29=$B$28)*('FASE DE GRUPOS'!$E$24:$E$29='FASE DE GRUPOS'!$D$24:$D$29)*('FASE DE GRUPOS'!$E$24:$E$29<>"")) | F28: =$C$28-$D$28-$E$28 | G28: =SUMPRODUCT(('FASE DE GRUPOS'!$C$24:$C$29=$B$28)*'FASE DE GRUPOS'!$D$24:$D$29)+SUMPRODUCT(('FASE DE GRUPOS'!$F$24:$F$29=$B$28)*'FASE DE GRUPOS'!$E$24:$E$29) | H28: =SUMPRODUCT(('FASE DE GRUPOS'!$C$24:$C$29=$B$28)*'FASE DE GRUPOS'!$E$24:$E$29)+SUMPRODUCT(('FASE DE GRUPOS'!$F$24:$F$29=$B$28)*'FASE DE GRUPOS'!$D$24:$D$29) | I28: =$G$28-$H$28 | J28: =3*$D$28+$E$28
A30: GRUPO E
A31: POS | B31: EQUIPO | C31: PJ | D31: G | E31: E | F31: P | G31: GF | H31: GC | I31: DIF | J31: PTS
A32: =1+SUMPRODUCT(($J$32:$J$35>$J$32)*1)+SUMPRODUCT(($J$32:$J$35=$J$32)*($I$32:$I$35>$I$32)*1)+SUMPRODUCT(($J$32:$J$35=$J$32)*($I$32:$I$35=$I$32)*($G$32:$G$35>$G$32)*1) | B32: Alemania | C32: =SUMPRODUCT(('FASE DE GRUPOS'!$C$31:$C$36=$B$32)*('FASE DE GRUPOS'!$D$31:$D$36<>""))+SUMPRODUCT(('FASE DE GRUPOS'!$F$31:$F$36=$B$32)*('FASE DE GRUPOS'!$E$31:$E$36<>"")) | D32: =SUMPRODUCT(('FASE DE GRUPOS'!$C$31:$C$36=$B$32)*('FASE DE GRUPOS'!$D$31:$D$36>'FASE DE GRUPOS'!$E$31:$E$36)*('FASE DE GRUPOS'!$D$31:$D$36<>""))+SUMPRODUCT(('FASE DE GRUPOS'!$F$31:$F$36=$B$32)*('FASE DE GRUPOS'!$E$31:$E$36>'FASE DE GRUPOS'!$D$31:$D$36)*('FASE DE GRUPOS'!$E$31:$E$36<>"")) | E32: =SUMPRODUCT(('FASE DE GRUPOS'!$C$31:$C$36=$B$32)*('FASE DE GRUPOS'!$D$31:$D$36='FASE DE GRUPOS'!$E$31:$E$36)*('FASE DE GRUPOS'!$D$31:$D$36<>""))+SUMPRODUCT(('FASE DE GRUPOS'!$F$31:$F$36=$B$32)*('FASE DE GRUPOS'!$E$31:$E$36='FASE DE GRUPOS'!$D$31:$D$36)*('FASE DE GRUPOS'!$E$31:$E$36<>"")) | F32: =$C$32-$D$32-$E$32 | G32: =SUMPRODUCT(('FASE DE GRUPOS'!$C$31:$C$36=$B$32)*'FASE DE GRUPOS'!$D$31:$D$36)+SUMPRODUCT(('FASE DE GRUPOS'!$F$31:$F$36=$B$32)*'FASE DE GRUPOS'!$E$31:$E$36) | H32: =SUMPRODUCT(('FASE DE GRUPOS'!$C$31:$C$36=$B$32)*'FASE DE GRUPOS'!$E$31:$E$36)+SUMPRODUCT(('FASE DE GRUPOS'!$F$31:$F$36=$B$32)*'FASE DE GRUPOS'!$D$31:$D$36) | I32: =$G$32-$H$32 | J32: =3*$D$32+$E$32
A33: =1+SUMPRODUCT(($J$32:$J$35>$J$33)*1)+SUMPRODUCT(($J$32:$J$35=$J$33)*($I$32:$I$35>$I$33)*1)+SUMPRODUCT(($J$32:$J$35=$J$33)*($I$32:$I$35=$I$33)*($G$32:$G$35>$G$33)*1) | B33: Curazao | C33: =SUMPRODUCT(('FASE DE GRUPOS'!$C$31:$C$36=$B$33)*('FASE DE GRUPOS'!$D$31:$D$36<>""))+SUMPRODUCT(('FASE DE GRUPOS'!$F$31:$F$36=$B$33)*('FASE DE GRUPOS'!$E$31:$E$36<>"")) | D33: =SUMPRODUCT(('FASE DE GRUPOS'!$C$31:$C$36=$B$33)*('FASE DE GRUPOS'!$D$31:$D$36>'FASE DE GRUPOS'!$E$31:$E$36)*('FASE DE GRUPOS'!$D$31:$D$36<>""))+SUMPRODUCT(('FASE DE GRUPOS'!$F$31:$F$36=$B$33)*('FASE DE GRUPOS'!$E$31:$E$36>'FASE DE GRUPOS'!$D$31:$D$36)*('FASE DE GRUPOS'!$E$31:$E$36<>"")) | E33: =SUMPRODUCT(('FASE DE GRUPOS'!$C$31:$C$36=$B$33)*('FASE DE GRUPOS'!$D$31:$D$36='FASE DE GRUPOS'!$E$31:$E$36)*('FASE DE GRUPOS'!$D$31:$D$36<>""))+SUMPRODUCT(('FASE DE GRUPOS'!$F$31:$F$36=$B$33)*('FASE DE GRUPOS'!$E$31:$E$36='FASE DE GRUPOS'!$D$31:$D$36)*('FASE DE GRUPOS'!$E$31:$E$36<>"")) | F33: =$C$33-$D$33-$E$33 | G33: =SUMPRODUCT(('FASE DE GRUPOS'!$C$31:$C$36=$B$33)*'FASE DE GRUPOS'!$D$31:$D$36)+SUMPRODUCT(('FASE DE GRUPOS'!$F$31:$F$36=$B$33)*'FASE DE GRUPOS'!$E$31:$E$36) | H33: =SUMPRODUCT(('FASE DE GRUPOS'!$C$31:$C$36=$B$33)*'FASE DE GRUPOS'!$E$31:$E$36)+SUMPRODUCT(('FASE DE GRUPOS'!$F$31:$F$36=$B$33)*'FASE DE GRUPOS'!$D$31:$D$36) | I33: =$G$33-$H$33 | J33: =3*$D$33+$E$33
A34: =1+SUMPRODUCT(($J$32:$J$35>$J$34)*1)+SUMPRODUCT(($J$32:$J$35=$J$34)*($I$32:$I$35>$I$34)*1)+SUMPRODUCT(($J$32:$J$35=$J$34)*($I$32:$I$35=$I$34)*($G$32:$G$35>$G$34)*1) | B34: Costa de Marfil | C34: =SUMPRODUCT(('FASE DE GRUPOS'!$C$31:$C$36=$B$34)*('FASE DE GRUPOS'!$D$31:$D$36<>""))+SUMPRODUCT(('FASE DE GRUPOS'!$F$31:$F$36=$B$34)*('FASE DE GRUPOS'!$E$31:$E$36<>"")) | D34: =SUMPRODUCT(('FASE DE GRUPOS'!$C$31:$C$36=$B$34)*('FASE DE GRUPOS'!$D$31:$D$36>'FASE DE GRUPOS'!$E$31:$E$36)*('FASE DE GRUPOS'!$D$31:$D$36<>""))+SUMPRODUCT(('FASE DE GRUPOS'!$F$31:$F$36=$B$34)*('FASE DE GRUPOS'!$E$31:$E$36>'FASE DE GRUPOS'!$D$31:$D$36)*('FASE DE GRUPOS'!$E$31:$E$36<>"")) | E34: =SUMPRODUCT(('FASE DE GRUPOS'!$C$31:$C$36=$B$34)*('FASE DE GRUPOS'!$D$31:$D$36='FASE DE GRUPOS'!$E$31:$E$36)*('FASE DE GRUPOS'!$D$31:$D$36<>""))+SUMPRODUCT(('FASE DE GRUPOS'!$F$31:$F$36=$B$34)*('FASE DE GRUPOS'!$E$31:$E$36='FASE DE GRUPOS'!$D$31:$D$36)*('FASE DE GRUPOS'!$E$31:$E$36<>"")) | F34: =$C$34-$D$34-$E$34 | G34: =SUMPRODUCT(('FASE DE GRUPOS'!$C$31:$C$36=$B$34)*'FASE DE GRUPOS'!$D$31:$D$36)+SUMPRODUCT(('FASE DE GRUPOS'!$F$31:$F$36=$B$34)*'FASE DE GRUPOS'!$E$31:$E$36) | H34: =SUMPRODUCT(('FASE DE GRUPOS'!$C$31:$C$36=$B$34)*'FASE DE GRUPOS'!$E$31:$E$36)+SUMPRODUCT(('FASE DE GRUPOS'!$F$31:$F$36=$B$34)*'FASE DE GRUPOS'!$D$31:$D$36) | I34: =$G$34-$H$34 | J34: =3*$D$34+$E$34
A35: =1+SUMPRODUCT(($J$32:$J$35>$J$35)*1)+SUMPRODUCT(($J$32:$J$35=$J$35)*($I$32:$I$35>$I$35)*1)+SUMPRODUCT(($J$32:$J$35=$J$35)*($I$32:$I$35=$I$35)*($G$32:$G$35>$G$35)*1) | B35: Ecuador | C35: =SUMPRODUCT(('FASE DE GRUPOS'!$C$31:$C$36=$B$35)*('FASE DE GRUPOS'!$D$31:$D$36<>""))+SUMPRODUCT(('FASE DE GRUPOS'!$F$31:$F$36=$B$35)*('FASE DE GRUPOS'!$E$31:$E$36<>"")) | D35: =SUMPRODUCT(('FASE DE GRUPOS'!$C$31:$C$36=$B$35)*('FASE DE GRUPOS'!$D$31:$D$36>'FASE DE GRUPOS'!$E$31:$E$36)*('FASE DE GRUPOS'!$D$31:$D$36<>""))+SUMPRODUCT(('FASE DE GRUPOS'!$F$31:$F$36=$B$35)*('FASE DE GRUPOS'!$E$31:$E$36>'FASE DE GRUPOS'!$D$31:$D$36)*('FASE DE GRUPOS'!$E$31:$E$36<>"")) | E35: =SUMPRODUCT(('FASE DE GRUPOS'!$C$31:$C$36=$B$35)*('FASE DE GRUPOS'!$D$31:$D$36='FASE DE GRUPOS'!$E$31:$E$36)*('FASE DE GRUPOS'!$D$31:$D$36<>""))+SUMPRODUCT(('FASE DE GRUPOS'!$F$31:$F$36=$B$35)*('FASE DE GRUPOS'!$E$31:$E$36='FASE DE GRUPOS'!$D$31:$D$36)*('FASE DE GRUPOS'!$E$31:$E$36<>"")) | F35: =$C$35-$D$35-$E$35 | G35: =SUMPRODUCT(('FASE DE GRUPOS'!$C$31:$C$36=$B$35)*'FASE DE GRUPOS'!$D$31:$D$36)+SUMPRODUCT(('FASE DE GRUPOS'!$F$31:$F$36=$B$35)*'FASE DE GRUPOS'!$E$31:$E$36) | H35: =SUMPRODUCT(('FASE DE GRUPOS'!$C$31:$C$36=$B$35)*'FASE DE GRUPOS'!$E$31:$E$36)+SUMPRODUCT(('FASE DE GRUPOS'!$F$31:$F$36=$B$35)*'FASE DE GRUPOS'!$D$31:$D$36) | I35: =$G$35-$H$35 | J35: =3*$D$35+$E$35
A37: GRUPO F
A38: POS | B38: EQUIPO | C38: PJ | D38: G | E38: E | F38: P | G38: GF | H38: GC | I38: DIF | J38: PTS
A39: =1+SUMPRODUCT(($J$39:$J$42>$J$39)*1)+SUMPRODUCT(($J$39:$J$42=$J$39)*($I$39:$I$42>$I$39)*1)+SUMPRODUCT(($J$39:$J$42=$J$39)*($I$39:$I$42=$I$39)*($G$39:$G$42>$G$39)*1) | B39: Países Bajos | C39: =SUMPRODUCT(('FASE DE GRUPOS'!$C$38:$C$43=$B$39)*('FASE DE GRUPOS'!$D$38:$D$43<>""))+SUMPRODUCT(('FASE DE GRUPOS'!$F$38:$F$43=$B$39)*('FASE DE GRUPOS'!$E$38:$E$43<>"")) | D39: =SUMPRODUCT(('FASE DE GRUPOS'!$C$38:$C$43=$B$39)*('FASE DE GRUPOS'!$D$38:$D$43>'FASE DE GRUPOS'!$E$38:$E$43)*('FASE DE GRUPOS'!$D$38:$D$43<>""))+SUMPRODUCT(('FASE DE GRUPOS'!$F$38:$F$43=$B$39)*('FASE DE GRUPOS'!$E$38:$E$43>'FASE DE GRUPOS'!$D$38:$D$43)*('FASE DE GRUPOS'!$E$38:$E$43<>"")) | E39: =SUMPRODUCT(('FASE DE GRUPOS'!$C$38:$C$43=$B$39)*('FASE DE GRUPOS'!$D$38:$D$43='FASE DE GRUPOS'!$E$38:$E$43)*('FASE DE GRUPOS'!$D$38:$D$43<>""))+SUMPRODUCT(('FASE DE GRUPOS'!$F$38:$F$43=$B$39)*('FASE DE GRUPOS'!$E$38:$E$43='FASE DE GRUPOS'!$D$38:$D$43)*('FASE DE GRUPOS'!$E$38:$E$43<>"")) | F39: =$C$39-$D$39-$E$39 | G39: =SUMPRODUCT(('FASE DE GRUPOS'!$C$38:$C$43=$B$39)*'FASE DE GRUPOS'!$D$38:$D$43)+SUMPRODUCT(('FASE DE GRUPOS'!$F$38:$F$43=$B$39)*'FASE DE GRUPOS'!$E$38:$E$43) | H39: =SUMPRODUCT(('FASE DE GRUPOS'!$C$38:$C$43=$B$39)*'FASE DE GRUPOS'!$E$38:$E$43)+SUMPRODUCT(('FASE DE GRUPOS'!$F$38:$F$43=$B$39)*'FASE DE GRUPOS'!$D$38:$D$43) | I39: =$G$39-$H$39 | J39: =3*$D$39+$E$39
A40: =1+SUMPRODUCT(($J$39:$J$42>$J$40)*1)+SUMPRODUCT(($J$39:$J$42=$J$40)*($I$39:$I$42>$I$40)*1)+SUMPRODUCT(($J$39:$J$42=$J$40)*($I$39:$I$42=$I$40)*($G$39:$G$42>$G$40)*1) | B40: Japón | C40: =SUMPRODUCT(('FASE DE GRUPOS'!$C$38:$C$43=$B$40)*('FASE DE GRUPOS'!$D$38:$D$43<>""))+SUMPRODUCT(('FASE DE GRUPOS'!$F$38:$F$43=$B$40)*('FASE DE GRUPOS'!$E$38:$E$43<>"")) | D40: =SUMPRODUCT(('FASE DE GRUPOS'!$C$38:$C$43=$B$40)*('FASE DE GRUPOS'!$D$38:$D$43>'FASE DE GRUPOS'!$E$38:$E$43)*('FASE DE GRUPOS'!$D$38:$D$43<>""))+SUMPRODUCT(('FASE DE GRUPOS'!$F$38:$F$43=$B$40)*('FASE DE GRUPOS'!$E$38:$E$43>'FASE DE GRUPOS'!$D$38:$D$43)*('FASE DE GRUPOS'!$E$38:$E$43<>"")) | E40: =SUMPRODUCT(('FASE DE GRUPOS'!$C$38:$C$43=$B$40)*('FASE DE GRUPOS'!$D$38:$D$43='FASE DE GRUPOS'!$E$38:$E$43)*('FASE DE GRUPOS'!$D$38:$D$43<>""))+SUMPRODUCT(('FASE DE GRUPOS'!$F$38:$F$43=$B$40)*('FASE DE GRUPOS'!$E$38:$E$43='FASE DE GRUPOS'!$D$38:$D$43)*('FASE DE GRUPOS'!$E$38:$E$43<>"")) | F40: =$C$40-$D$40-$E$40 | G40: =SUMPRODUCT(('FASE DE GRUPOS'!$C$38:$C$43=$B$40)*'FASE DE GRUPOS'!$D$38:$D$43)+SUMPRODUCT(('FASE DE GRUPOS'!$F$38:$F$43=$B$40)*'FASE DE GRUPOS'!$E$38:$E$43) | H40: =SUMPRODUCT(('FASE DE GRUPOS'!$C$38:$C$43=$B$40)*'FASE DE GRUPOS'!$E$38:$E$43)+SUMPRODUCT(('FASE DE GRUPOS'!$F$38:$F$43=$B$40)*'FASE DE GRUPOS'!$D$38:$D$43) | I40: =$G$40-$H$40 | J40: =3*$D$40+$E$40
A41: =1+SUMPRODUCT(($J$39:$J$42>$J$41)*1)+SUMPRODUCT(($J$39:$J$42=$J$41)*($I$39:$I$42>$I$41)*1)+SUMPRODUCT(($J$39:$J$42=$J$41)*($I$39:$I$42=$I$41)*($G$39:$G$42>$G$41)*1) | B41: Suecia | C41: =SUMPRODUCT(('FASE DE GRUPOS'!$C$38:$C$43=$B$41)*('FASE DE GRUPOS'!$D$38:$D$43<>""))+SUMPRODUCT(('FASE DE GRUPOS'!$F$38:$F$43=$B$41)*('FASE DE GRUPOS'!$E$38:$E$43<>"")) | D41: =SUMPRODUCT(('FASE DE GRUPOS'!$C$38:$C$43=$B$41)*('FASE DE GRUPOS'!$D$38:$D$43>'FASE DE GRUPOS'!$E$38:$E$43)*('FASE DE GRUPOS'!$D$38:$D$43<>""))+SUMPRODUCT(('FASE DE GRUPOS'!$F$38:$F$43=$B$41)*('FASE DE GRUPOS'!$E$38:$E$43>'FASE DE GRUPOS'!$D$38:$D$43)*('FASE DE GRUPOS'!$E$38:$E$43<>"")) | E41: =SUMPRODUCT(('FASE DE GRUPOS'!$C$38:$C$43=$B$41)*('FASE DE GRUPOS'!$D$38:$D$43='FASE DE GRUPOS'!$E$38:$E$43)*('FASE DE GRUPOS'!$D$38:$D$43<>""))+SUMPRODUCT(('FASE DE GRUPOS'!$F$38:$F$43=$B$41)*('FASE DE GRUPOS'!$E$38:$E$43='FASE DE GRUPOS'!$D$38:$D$43)*('FASE DE GRUPOS'!$E$38:$E$43<>"")) | F41: =$C$41-$D$41-$E$41 | G41: =SUMPRODUCT(('FASE DE GRUPOS'!$C$38:$C$43=$B$41)*'FASE DE GRUPOS'!$D$38:$D$43)+SUMPRODUCT(('FASE DE GRUPOS'!$F$38:$F$43=$B$41)*'FASE DE GRUPOS'!$E$38:$E$43) | H41: =SUMPRODUCT(('FASE DE GRUPOS'!$C$38:$C$43=$B$41)*'FASE DE GRUPOS'!$E$38:$E$43)+SUMPRODUCT(('FASE DE GRUPOS'!$F$38:$F$43=$B$41)*'FASE DE GRUPOS'!$D$38:$D$43) | I41: =$G$41-$H$41 | J41: =3*$D$41+$E$41
A42: =1+SUMPRODUCT(($J$39:$J$42>$J$42)*1)+SUMPRODUCT(($J$39:$J$42=$J$42)*($I$39:$I$42>$I$42)*1)+SUMPRODUCT(($J$39:$J$42=$J$42)*($I$39:$I$42=$I$42)*($G$39:$G$42>$G$42)*1) | B42: Túnez | C42: =SUMPRODUCT(('FASE DE GRUPOS'!$C$38:$C$43=$B$42)*('FASE DE GRUPOS'!$D$38:$D$43<>""))+SUMPRODUCT(('FASE DE GRUPOS'!$F$38:$F$43=$B$42)*('FASE DE GRUPOS'!$E$38:$E$43<>"")) | D42: =SUMPRODUCT(('FASE DE GRUPOS'!$C$38:$C$43=$B$42)*('FASE DE GRUPOS'!$D$38:$D$43>'FASE DE GRUPOS'!$E$38:$E$43)*('FASE DE GRUPOS'!$D$38:$D$43<>""))+SUMPRODUCT(('FASE DE GRUPOS'!$F$38:$F$43=$B$42)*('FASE DE GRUPOS'!$E$38:$E$43>'FASE DE GRUPOS'!$D$38:$D$43)*('FASE DE GRUPOS'!$E$38:$E$43<>"")) | E42: =SUMPRODUCT(('FASE DE GRUPOS'!$C$38:$C$43=$B$42)*('FASE DE GRUPOS'!$D$38:$D$43='FASE DE GRUPOS'!$E$38:$E$43)*('FASE DE GRUPOS'!$D$38:$D$43<>""))+SUMPRODUCT(('FASE DE GRUPOS'!$F$38:$F$43=$B$42)*('FASE DE GRUPOS'!$E$38:$E$43='FASE DE GRUPOS'!$D$38:$D$43)*('FASE DE GRUPOS'!$E$38:$E$43<>"")) | F42: =$C$42-$D$42-$E$42 | G42: =SUMPRODUCT(('FASE DE GRUPOS'!$C$38:$C$43=$B$42)*'FASE DE GRUPOS'!$D$38:$D$43)+SUMPRODUCT(('FASE DE GRUPOS'!$F$38:$F$43=$B$42)*'FASE DE GRUPOS'!$E$38:$E$43) | H42: =SUMPRODUCT(('FASE DE GRUPOS'!$C$38:$C$43=$B$42)*'FASE DE GRUPOS'!$E$38:$E$43)+SUMPRODUCT(('FASE DE GRUPOS'!$F$38:$F$43=$B$42)*'FASE DE GRUPOS'!$D$38:$D$43) | I42: =$G$42-$H$42 | J42: =3*$D$42+$E$42
A44: GRUPO G
A45: POS | B45: EQUIPO | C45: PJ | D45: G | E45: E | F45: P | G45: GF | H45: GC | I45: DIF | J45: PTS
A46: =1+SUMPRODUCT(($J$46:$J$49>$J$46)*1)+SUMPRODUCT(($J$46:$J$49=$J$46)*($I$46:$I$49>$I$46)*1)+SUMPRODUCT(($J$46:$J$49=$J$46)*($I$46:$I$49=$I$46)*($G$46:$G$49>$G$46)*1) | B46: Bélgica | C46: =SUMPRODUCT(('FASE DE GRUPOS'!$C$45:$C$50=$B$46)*('FASE DE GRUPOS'!$D$45:$D$50<>""))+SUMPRODUCT(('FASE DE GRUPOS'!$F$45:$F$50=$B$46)*('FASE DE GRUPOS'!$E$45:$E$50<>"")) | D46: =SUMPRODUCT(('FASE DE GRUPOS'!$C$45:$C$50=$B$46)*('FASE DE GRUPOS'!$D$45:$D$50>'FASE DE GRUPOS'!$E$45:$E$50)*('FASE DE GRUPOS'!$D$45:$D$50<>""))+SUMPRODUCT(('FASE DE GRUPOS'!$F$45:$F$50=$B$46)*('FASE DE GRUPOS'!$E$45:$E$50>'FASE DE GRUPOS'!$D$45:$D$50)*('FASE DE GRUPOS'!$E$45:$E$50<>"")) | E46: =SUMPRODUCT(('FASE DE GRUPOS'!$C$45:$C$50=$B$46)*('FASE DE GRUPOS'!$D$45:$D$50='FASE DE GRUPOS'!$E$45:$E$50)*('FASE DE GRUPOS'!$D$45:$D$50<>""))+SUMPRODUCT(('FASE DE GRUPOS'!$F$45:$F$50=$B$46)*('FASE DE GRUPOS'!$E$45:$E$50='FASE DE GRUPOS'!$D$45:$D$50)*('FASE DE GRUPOS'!$E$45:$E$50<>"")) | F46: =$C$46-$D$46-$E$46 | G46: =SUMPRODUCT(('FASE DE GRUPOS'!$C$45:$C$50=$B$46)*'FASE DE GRUPOS'!$D$45:$D$50)+SUMPRODUCT(('FASE DE GRUPOS'!$F$45:$F$50=$B$46)*'FASE DE GRUPOS'!$E$45:$E$50) | H46: =SUMPRODUCT(('FASE DE GRUPOS'!$C$45:$C$50=$B$46)*'FASE DE GRUPOS'!$E$45:$E$50)+SUMPRODUCT(('FASE DE GRUPOS'!$F$45:$F$50=$B$46)*'FASE DE GRUPOS'!$D$45:$D$50) | I46: =$G$46-$H$46 | J46: =3*$D$46+$E$46
...

Sheet ELIMINATORIAS
A1: P# | B1: FASE | C1: LOCAL | E1: VISITANTE | F1: Fecha (Col) | G1: Estadio
A2: 73 | B2: 16avos | C2: 2º Gpo A | D2: vs | E2: 2º Gpo B | F2: dom 28 jun · 2:00 PM | G2: Los Angeles Stadium
A3: 76 | B3: 16avos | C3: 1º Gpo C | D3: vs | E3: 2º Gpo F | F3: lun 29 jun · 12:00 PM | G3: Houston Stadium
A4: 74 | B4: 16avos | C4: 1º Gpo E | D4: vs | E4: 3º de A/B/C/D/F | F4: lun 29 jun · 3:30 PM | G4: Boston Stadium
A5: 75 | B5: 16avos | C5: 1º Gpo F | D5: vs | E5: 2º Gpo C | F5: lun 29 jun · 8:00 PM | G5: Monterrey Stadium
A6: 78 | B6: 16avos | C6: 2º Gpo E | D6: vs | E6: 2º Gpo I | F6: mar 30 jun · 12:00 PM | G6: Dallas Stadium
A7: 77 | B7: 16avos | C7: 1º Gpo I | D7: vs | E7: 3º de C/D/F/G/H | F7: mar 30 jun · 4:00 PM | G7: New York/New Jersey Stadium
A8: 79 | B8: 16avos | C8: 1º Gpo A | D8: vs | E8: 3º de C/E/F/H/I | F8: mar 30 jun · 8:00 PM | G8: Mexico City Stadium
A9: 80 | B9: 16avos | C9: 1º Gpo L | D9: vs | E9: 3º de E/H/I/J/K | F9: mié 1 jul · 11:00 AM | G9: Atlanta Stadium
A10: 82 | B10: 16avos | C10: 1º Gpo G | D10: vs | E10: 3º de A/E/H/I/J | F10: mié 1 jul · 3:00 PM | G10: Seattle Stadium
A11: 81 | B11: 16avos | C11: 1º Gpo D | D11: vs | E11: 3º de B/E/F/I/J | F11: mié 1 jul · 7:00 PM | G11: San Francisco Bay Area Stadium
A12: 84 | B12: 16avos | C12: 1º Gpo H | D12: vs | E12: 2º Gpo J | F12: jue 2 jul · 2:00 PM | G12: Los Angeles Stadium
A13: 83 | B13: 16avos | C13: 2º Gpo K | D13: vs | E13: 2º Gpo L | F13: jue 2 jul · 6:00 PM | G13: Toronto Stadium
... A33: 104 | B33: Final/3º | C33: To be announced | D33: vs | E33: To be announced | F33: dom 19 jul · 2:00 PM | G33: New York/New Jersey Stadium
